Workbook
Name DEFENDER_CAP_noVFD: SUM('[1]Backup Data'!$L$34,'[1]Backup Data'!$N$34,'[1]Backup Data'!$Q$34)
Name DEFENDER_CAP_VFD: '[1]Backup Data'!$L$34+'[1]Backup Data'!$N$34+'[1]Backup Data'!$P$34+'[1]Backup Data'!$Q$34
Name DEFENDER_OP_noVFD: SUM('[1]Backup Data'!$S$34:$AB$34)
Name DEFENDER_OP_VFD: '[1]Backup Data'!$S$34+'[1]Backup Data'!$T$34+'[1]Backup Data'!$U$34+'[1]Backup Data'!$V$34+'[1]Backup Data'!$X$34+'[1]Backup Data'!$Z$34
Name INFLATION: '[1]Backup Data'!$B$2
Name SAND_CAP_noVFD: '[1]Backup Data'!$L$18+'[1]Backup Data'!$N$18+'[1]Backup Data'!$O$18+'[1]Backup Data'!$P$18
Name SAND_CAP_VFD: SUM('[1]Backup Data'!$L$18,'[1]Backup Data'!$N$18,'[1]Backup Data'!$O$18,'[1]Backup Data'!$P$18,'[1]Backup Data'!$Q$18)
Name SAND_MEDIA_CHANGE: ('[1]Backup Data'!$K$18/100*22.3*2)+('[1]Backup Data'!$K$18/100*10*2)
Name SAND_OP_noVFD: SUM('[1]Backup Data'!$S$18,'[1]Backup Data'!$T$18,'[1]Backup Data'!$U$18,'[1]Backup Data'!$V$18,'[1]Backup Data'!$Z$18)
Name SAND_OP_VFD: SUM('[1]Backup Data'!$S$18,'[1]Backup Data'!$T$18,'[1]Backup Data'!$U$18,'[1]Backup Data'!$V$18,'[1]Backup Data'!$X$18)

Sheet INPUTS
A1: Defender® Cost Savings Analysis
A2: PROJECT INFORMATION
A3: PROJECT: | H3: DATE:
A4: LOCATION: | H4: PREPARED FOR:
H5: PREPARED BY:
A7: POOL SYSTEM DATA
A8: POOL DESCRIPTION | D8: I/O | E8: Flow (gpm) | G8: POOL DESCRIPTION | K8: I/O | L8: Flow (gpm)
A9: Pool-1 | D9: I | E9: 0 | G9: Pool-6
A10: Pool-2 | G10: Pool-7
A11: Pool-3 | G11: Pool-8
A12: Pool-4 | G12: Pool-9
A13: Pool-5 | G13: Pool-10
A15: OPERATING COST VARIABLES
A16: VARIABLES | C16: FORMULAS & DEFINITIONS | J16: VALUES | L16: UNIT
A17: MECHANICAL SPACE VALUE | C17: Cost per ft² to construct a room adequate to house filter equipment (indoor construction). | J17: 120 | L17: $/ft²
A18: INSTALLATION LABOR VARIANCE | C18: Sand filters require an installation labor variance @ historical average cost of 15% of the filter. | J18: 0.15 | L18: $
A19: MEDIA LOADING: SAND FILTER | C19: Average cost to load media based on historical averages for time and labor. | J19: 3 | L19: $/bag
A20: MEDIA COST: SAND FILTER | C20: Based on average market rate for #20 Silica Sand and 1/8 X 1/4 Pea Gravel. Weights drawn from corresponding filter data. | J20: 17.8 | L20: $/100lb
A21: MEDIA COST: DEFENDER FILTER | C21: Based on average market rate for Perlite Filter Media. Annual Defender Filter Media Cost = Media weight in filter (from table) x Defender backwash frequency. | J21: 0.94 | L21: $/lb
A22: BACKWASH VOL: SAND (BVS) | C22: BVS = Backwash Rate x Total Filter Surface Area x Backwash Duration x Backwash Frequency. | I22: Rate | J22: 20 | L22: gpm/ft²
I23: Surface Area | J23: From Table | L23: ft²
I24: Duration | J24: 5 | L24: minutes
I25: Frequency | J25: 104 | L25: #/season
A26: BACKWASH VOL: DEFENDER (BVD) | C26: BVD = Total Tank Volume x 2 x Media Replacement Frequency. | I26: Tank Volume | J26: From Table | L26: gal
I27: Frequency | J27: 12 | L27: #/season
A28: POTABLE WATER USAGE | C28: Potable Water Usage fee includes a "Volume Charge" only and does not include the monthly meter charge. See "Backwash Volume" for water usage volume calculation. | J28: 3.5 | L28: $/1000 gal
A29: SANITARY SEWER FEE | C29: Sanitary Sewer Fee = (Monthly Capacity Charge + Monthly Usage Charge) x annual sewerage volume. | J29: 3.5 | L29: $/1000 gal
A30: MAKE-UP WATER: CHEMICALS (MWC) | C30: MWC Cost = Water savings in gallons x Average market $cost/gal for pool chemicals. | J30: 3 | L30: $/1000 gal
A31: MAKE-UP WATER: HEAT (MWH) | C31: Represents cost to reheat backwash makeup water by average temperature delta°. MWH Cost = Backwash Vol. x 8.33#/gal x Conversion Factor x Delta° x $/therm. | I31: Temp Delta | J31: 30 | L31: degrees F
I32: Cost/Therm | J32: 0.9 | L32: $/therm
A33: OPERATING DAYS PER SEASON | C33: Average number of days of operation each year across all pools included in the project. | J33: 365 | L33: days
A34: ELECTRICAL COSTS | C34: Pump Motor HP x.746 Rating Conversion x $Cost/Kw x 24 hrs x Average Operating Days. | I34: Kw | J34: 0.12 | L34: $/Kw
A35: ANNUAL INCREASE | C35: Average cumulative increase in labor, materials and maintenance costs (applies to both Sand and Defender filter installations). | J35: 0.07 | L35: %
A36: COMPRESSORS | C36: Number of Air Compressor units needed for this project. | J36: 1 | L36: #
A37: DEFENDER TOOL KITS | C37: Number of Defender Tool Kits needed for this project. | J37: 1 | L37: #

Sheet GRAPH
B3: PROJECT NAME: | C3: =INPUTS!C3 -> 0 | L3: PREPARED BY: | M3: =INPUTS!I5 -> 0
B4: LOCATION: | C4: =INPUTS!C4 -> 0 | L4: PHONE: | M4: 800-832-8002
B5: PREPARED FOR: | C5: =INPUTS!I4 -> 0 | L5: FAX: | M5: 401-821-7129
B6: DATE: | C6: =INPUTS!I3 -> 0 | L6: WEBSITE: | M6: www.DefenderFilter.com
B10: 10 YEAR LIFE-CYCLE COST INCLUDING CAPITAL INVESTMENT | O10: Water Savings
O12: =1-DETAIL!O35/DETAIL!O17 -> #DIV/0!
O13: Annual Water Savings
O15: =(DETAIL!O17-DETAIL!O35)*(10) -> 0
O16: Gallons Saved Over 10 Years
O19: Adj. ROI Payback
O21: =VLOOKUP(0,'GRAPH DATA'!A27:H266,8) -> #N/A
O22: =INPUTS!J33 -> 365
O25: Electrical Savings
O27: =1-DETAIL!W35/DETAIL!W17 -> #DIV/0!
O28: Annual Electrical Savings
O30: =SUMMARY!E24/0.1 -> 0
O31: kWh Saved Over 10 Years
C35: CAPITAL | D35: 1YR | E35: 2YR | F35: 3YR | G35: 4YR | H35: 5YR | I35: 6YR | J35: 7YR | K35: 8YR | L35: 9YR | M35: 10YR
B36: DEFENDER: | C36: =SUMMARY!D9 -> 1710.0016 | D36: ='GRAPH DATA'!B23 -> 1710.0016 | E36: ='GRAPH DATA'!C23 -> 1710.0016 | F36: ='GRAPH DATA'!D23 -> 1710.0016 | G36: ='GRAPH DATA'!E23 -> 1710.0016 | H36: ='GRAPH DATA'!F23 -> 1710.0016 | I36: ='GRAPH DATA'!G23 -> 1710.0016 | J36: ='GRAPH DATA'!H23 -> 1710.0016 | K36: ='GRAPH DATA'!I23 -> 1710.0016 | ... M36: ='GRAPH DATA'!K23 -> 1710.0016
B37: SAND: | C37: =SUMMARY!C9 -> 0 | D37: =+'GRAPH DATA'!B11 -> 0 | E37: =+'GRAPH DATA'!C11 -> 0 | F37: =+'GRAPH DATA'!D11 -> 0 | G37: =+'GRAPH DATA'!E11 -> 0 | H37: =+'GRAPH DATA'!F11 -> 0 | I37: =+'GRAPH DATA'!G11 -> 0 | J37: =+'GRAPH DATA'!H11 -> 0 | K37: =+'GRAPH DATA'!I11 -> 0 | ... M37: =+'GRAPH DATA'!K11 -> 0
B38: Defender 10 Year Savings Forecast: | K38: =M37-M36 -> -1710.0016

Sheet SUMMARY
B1: DEFENDER COST SAVINGS ANALYSIS: SUMMARY
B3: INITIAL CAPITAL EXPENSES
B4: ITEM / DESCRIPTION | C4: SAND FILTER COST | D4: DEFENDER FILTER COST | E4: COST VARIANCE
B5: FILTER PURCHASE PRICE | C5: =DETAIL!I17 -> 0 | D5: =DETAIL!I35 -> 1710.0016 | E5: =C5-D5 -> -1710.0016
B6: MECHANICAL SPACE | C6: =DETAIL!K17 -> 0 | D6: =DETAIL!K35 -> 0 | E6: =C6-D6 -> 0
B7: INSTALLATION LABOR VARIANCE | C7: =DETAIL!L17 -> 0 | D7: 0 | E7: =C7-D7 -> 0
B8: FILTER MEDIA | C8: =DETAIL!N17 -> 0 | D8: =DETAIL!N35 -> 0 | E8: =C8-D8 -> 0
B9: TOTAL CAPITAL COSTS: | C9: =SUM(C5:C8) -> 0 | D9: =SUM(D5:D8) -> 1710.0016 | E9: =C9-D9 -> -1710.0016
B11: ANNUAL OPERATING EXPENSES
B12: ITEM / DESCRIPTION | C12: SAND FILTER COST | D12: DEFENDER FILTER COST | E12: COST VARIANCE
B13: ELECTRICAL COSTS | C13: =DETAIL!W17 -> 0 | D13: =DETAIL!W35 -> 0 | E13: =C13-D13 -> 0
B14: POTABLE WATER FEE | C14: =DETAIL!P17 -> 0 | D14: =DETAIL!P35 -> 0 | E14: =C14-D14 -> 0
B15: MAKE-UP: CHEMICALS | C15: =DETAIL!R17 -> 0 | D15: =DETAIL!R35 -> 0 | E15: =C15-D15 -> 0
B16: MAKE-UP: HEAT | C16: =DETAIL!S17 -> 0 | D16: =DETAIL!S35 -> 0 | E16: =C16-D16 -> 0
B17: SANITARY SEWER FEE | C17: =DETAIL!Q17 -> 0 | D17: =DETAIL!Q35 -> 0 | E17: =C17-D17 -> 0
B18: PERLITE MEDIA | C18: 0 | D18: =DETAIL!U35 -> 0 | E18: =C18-D18 -> 0
B19: ANNUAL OPERATING COSTS: | C19: =SUM(C13:C18) -> 0 | D19: =SUM(D13:D18) -> 0 | E19: =C19-D19 -> 0
B21: FILTER 10 YEAR SAVINGS FORECAST
B22: ITEM / DESCRIPTION | C22: SAND FILTER COST | D22: DEFENDER FILTER COST | E22: COST VARIANCE
B23: CAPITAL COST | C23: =C9 -> 0 | D23: =D9 -> 1710.0016 | E23: =C23-D23 -> -1710.0016
B24: ELECTRICAL COSTS* | C24: ='GRAPH DATA'!K4 -> 0 | D24: ='GRAPH DATA'!K16 -> 0 | E24: =C24-D24 -> 0
B25: POTABLE WATER FEE* | C25: ='GRAPH DATA'!K5 -> 0 | D25: ='GRAPH DATA'!K17 -> 0 | E25: =C25-D25 -> 0
B26: MAKE-UP: CHEMICALS* | C26: ='GRAPH DATA'!K6 -> 0 | D26: ='GRAPH DATA'!K18 -> 0 | E26: =C26-D26 -> 0
B27: MAKE-UP: HEAT* | C27: ='GRAPH DATA'!K7 -> 0 | D27: ='GRAPH DATA'!K19 -> 0 | E27: =C27-D27 -> 0
B28: SANITARY SEWER FEE* | C28: ='GRAPH DATA'!K8 -> 0 | D28: ='GRAPH DATA'!K20 -> 0 | E28: =C28-D28 -> 0
B29: PERLITE MEDIA* | C29: 0 | D29: ='GRAPH DATA'!K21 -> 0 | E29: =C29-D29 -> 0
B30: SAND MEDIA REPLACEMENT** | C30: ='GRAPH DATA'!K9 -> 0 | D30: 0 | E30: =C30-D30 -> 0
B31: MEDIA REPLACEMENT (LABOR)*** | C31: ='GRAPH DATA'!K10 -> 0 | D31: 0 | E31: =C31-D31 -> 0
B32: GRAND TOTAL SAVINGS: | E32: =SUM(E23:E31) -> -1710.0016
B34: RAW ROI PAYBACK PROJECTION | C34: CAPITAL COST VARIANCE ÷ | D34: OPERATING COST VARIANCE = | E34: PAYBACK PERIOD (MONTHS)
C35: =E9 -> -1710.0016 | D35: =E19 -> 0 | E35: =(-C35/D35*12) -> #DIV/0!
B37: *COSTS INCLUDE ANNUAL INCREASE FOR LABOR, MATERIALS AND MAINTENANCE
B38: **SAND MEDIA REPLACEMENT AT 5 & 10 YEAR INTERVALS - PRICE BASED ON PROJECTED FUTURE COST
B39: ***MEDIA REPLACEMENT LABOR BASED ON HISTORICAL AVERAGES FACTORED FOR ANNUAL COST INCREASES
B41: PROJECT NAME: | C41: =INPUTS!C3 -> 0
B42: LOCATION: | C42: =INPUTS!C4 -> 0
B43: CONTACT NAME: | C43: =INPUTS!I4 -> 0
B44: PREPARED BY: | C44: =INPUTS!I5 -> 0
B45: DATE: | C45: =INPUTS!I3 -> 0
G62: Totals
...

Sheet DETAIL
A1: DEFENDER COST SAVINGS ANALYSIS: DETAIL
A3: SAND FILTER CAPITAL & OPERATING COSTS
A4: POOL DATA | C4: SAND FILTER DATA | I4: CAPITAL COSTS | O4: ANNUAL OPERATING COSTS * SAND FILTER
A5: Pool Description | B5: Flow (gpm) | C5: Qty | D5: NB Model # | E5: Filter Surface Area (sf) | F5: Filtration Rate (gpm/sf) | G5: B/W Rates @ 20 gpm/sf (gpm) | H5: Total Media Wt (lb) | I5: Equipment Purchase Price | J5: MECHANICAL SPACE | L5: Install Labor | M5: Media Loading Cost | N5: Sand Media Cost | O5: FILTER BACKWASH | V5: PUMP DATA
J6: Footprint (sf) | K6: Cost | O6: Volume (gal) | P6: Potable Water | Q6: Sanitary Sewer Fee | R6: Make-up Water Chem | S6: Make-up Water Heat | V6: Brake HP Req'd @ 70'TDH | W6: Electrical Cost w/VFD
A7: =INPUTS!B9 -> 0 | B7: =INPUTS!E9 -> 0 | C7: =VLOOKUP(INPUTS!E9, TABLE!A4:R37, 2) -> 0 | D7: =VLOOKUP(INPUTS!E9, TABLE!A4:R37, 3) -> 0 | E7: =VLOOKUP(INPUTS!E9, TABLE!A4:R37, 4) -> 0 | F7: =IF(E7=0,0,INPUTS!E9/E7) -> 0 | G7: =E7*INPUTS!J22 -> 0 | H7: =VLOOKUP(INPUTS!E9, TABLE!A4:R37, 5) -> 0 | I7: =VLOOKUP(INPUTS!E9, TABLE!A4:R37, 10) -> 0 | J7: =VLOOKUP(INPUTS!E9, TABLE!A4:R37, 6) -> 0 | K7: =INPUTS!$J$17*J7 -> 0 | L7: =I7*INPUTS!$J$18 -> 0 | M7: =H7*INPUTS!$J$19/100 -> 0 | N7: =H7*INPUTS!$J$20/100 -> 0 | O7: =E7*INPUTS!J22*INPUTS!J24*INPUTS!J25 -> 0 | P7: =O7*INPUTS!$J$28/1000 -> 0 | Q7: =O7/1000*INPUTS!J29 -> 0 | R7: =O7*INPUTS!J30/1000 -> 0 | S7: =O7*8.33*1.2*INPUTS!$J$31/100000*INPUTS!$J$32 -> 0 | V7: =SUM((INPUTS!E9*70)/3960)/0.8 -> 0 | W7: =SUM(V7*0.746)*INPUTS!$J$34*24*INPUTS!$J$33*0.512 -> 0
A8: =INPUTS!B10 -> 0 | B8: =INPUTS!E10 -> 0 | C8: =VLOOKUP(INPUTS!E10, TABLE!A4:R37, 2) -> 0 | D8: =VLOOKUP(INPUTS!E10, TABLE!A4:R37, 3) -> 0 | E8: =VLOOKUP(INPUTS!E10, TABLE!A4:R37, 4) -> 0 | F8: =IF(E8=0,0,INPUTS!E10/E8) -> 0 | G8: =E8*INPUTS!J22 -> 0 | H8: =VLOOKUP(INPUTS!E10, TABLE!A4:R37, 5) -> 0 | I8: =VLOOKUP(INPUTS!E10, TABLE!A4:R37, 10) -> 0 | J8: =VLOOKUP(INPUTS!E10, TABLE!A4:R37, 6) -> 0 | K8: =INPUTS!$J$17*J8 -> 0 | L8: =I8*INPUTS!$J$18 -> 0 | M8: =H8*INPUTS!$J$19/100 -> 0 | N8: =H8*INPUTS!$J$20/100 -> 0 | O8: =E8*INPUTS!J22*INPUTS!J24*INPUTS!J25 -> 0 | P8: =O8*INPUTS!$J$28/1000 -> 0 | Q8: =O8/1000*INPUTS!J29 -> 0 | R8: =O8*INPUTS!J30/1000 -> 0 | S8: =O8*8.33*1.2*INPUTS!$J$31/100000*INPUTS!$J$32 -> 0 | V8: =SUM((INPUTS!E10*70)/3960)/0.8 -> 0 | W8: =SUM(V8*0.746)*INPUTS!$J$34*24*INPUTS!$J$33*0.512 -> 0
A9: =INPUTS!B11 -> 0 | B9: =INPUTS!E11 -> 0 | C9: =VLOOKUP(INPUTS!E11, TABLE!A4:R37, 2) -> 0 | D9: =VLOOKUP(INPUTS!E11, TABLE!A4:R37, 3) -> 0 | E9: =VLOOKUP(INPUTS!E11, TABLE!A4:R37, 4) -> 0 | F9: =IF(E9=0,0,INPUTS!E11/E9) -> 0 | G9: =E9*INPUTS!J22 -> 0 | H9: =VLOOKUP(INPUTS!E11, TABLE!A4:R37, 5) -> 0 | I9: =VLOOKUP(INPUTS!E11, TABLE!A4:R37, 10) -> 0 | J9: =VLOOKUP(INPUTS!E11, TABLE!A4:R37, 6) -> 0 | K9: =INPUTS!$J$17*J9 -> 0 | L9: =I9*INPUTS!$J$18 -> 0 | M9: =H9*INPUTS!$J$19/100 -> 0 | N9: =H9*INPUTS!$J$20/100 -> 0 | O9: =E9*INPUTS!J22*INPUTS!J24*INPUTS!J25 -> 0 | P9: =O9*INPUTS!$J$28/1000 -> 0 | Q9: =O9/1000*INPUTS!J29 -> 0 | R9: =O9*INPUTS!J30/1000 -> 0 | S9: =O9*8.33*1.2*INPUTS!$J$31/100000*INPUTS!$J$32 -> 0 | V9: =SUM((INPUTS!E11*70)/3960)/0.8 -> 0 | W9: =SUM(V9*0.746)*INPUTS!$J$34*24*INPUTS!$J$33*0.512 -> 0
A10: =INPUTS!B12 -> 0 | B10: =INPUTS!E12 -> 0 | C10: =VLOOKUP(INPUTS!E12, TABLE!A4:R37, 2) -> 0 | D10: =VLOOKUP(INPUTS!E12, TABLE!A4:R37, 3) -> 0 | E10: =VLOOKUP(INPUTS!E12, TABLE!A4:R37, 4) -> 0 | F10: =IF(E10=0,0,INPUTS!E12/E10) -> 0 | G10: =E10*INPUTS!J22 -> 0 | H10: =VLOOKUP(INPUTS!E12, TABLE!A4:R37, 5) -> 0 | I10: =VLOOKUP(INPUTS!E12, TABLE!A4:R37, 10) -> 0 | J10: =VLOOKUP(INPUTS!E12, TABLE!A4:R37, 6) -> 0 | K10: =INPUTS!$J$17*J10 -> 0 | L10: =I10*INPUTS!$J$18 -> 0 | M10: =H10*INPUTS!$J$19/100 -> 0 | N10: =H10*INPUTS!$J$20/100 -> 0 | O10: =E10*INPUTS!J22*INPUTS!J24*INPUTS!J25 -> 0 | P10: =O10*INPUTS!$J$28/1000 -> 0 | Q10: =O10/1000*INPUTS!J29 -> 0 | R10: =O10*INPUTS!J30/1000 -> 0 | S10: =O10*8.33*1.2*INPUTS!$J$31/100000*INPUTS!$J$32 -> 0 | V10: =SUM((INPUTS!E12*70)/3960)/0.8 -> 0 | W10: =SUM(V10*0.746)*INPUTS!$J$34*24*INPUTS!$J$33*0.512 -> 0
A11: =INPUTS!B13 -> 0 | B11: =INPUTS!E13 -> 0 | C11: =VLOOKUP(INPUTS!E13, TABLE!A4:R37, 2) -> 0 | D11: =VLOOKUP(INPUTS!E13, TABLE!A4:R37, 3) -> 0 | E11: =VLOOKUP(INPUTS!E13, TABLE!A4:R37, 4) -> 0 | F11: =IF(E11=0,0,INPUTS!E13/E11) -> 0 | G11: =E11*INPUTS!J22 -> 0 | H11: =VLOOKUP(INPUTS!E13, TABLE!A4:R37, 5) -> 0 | I11: =VLOOKUP(INPUTS!E13, TABLE!A4:R37, 10) -> 0 | J11: =VLOOKUP(INPUTS!E13, TABLE!A4:R37, 6) -> 0 | K11: =INPUTS!$J$17*J11 -> 0 | L11: =I11*INPUTS!$J$18 -> 0 | M11: =H11*INPUTS!$J$19/100 -> 0 | N11: =H11*INPUTS!$J$20/100 -> 0 | O11: =E11*INPUTS!J22*INPUTS!J24*INPUTS!J25 -> 0 | P11: =O11*INPUTS!$J$28/1000 -> 0 | Q11: =O11/1000*INPUTS!J29 -> 0 | R11: =O11*INPUTS!J30/1000 -> 0 | S11: =O11*8.33*1.2*INPUTS!$J$31/100000*INPUTS!$J$32 -> 0 | V11: =SUM((INPUTS!E13*70)/3960)/0.8 -> 0 | W11: =SUM(V11*0.746)*INPUTS!$J$34*24*INPUTS!$J$33*0.512 -> 0
A12: =INPUTS!H9 -> 0 | B12: =INPUTS!L9 -> 0 | C12: =VLOOKUP(INPUTS!L9, TABLE!A4:R37, 2) -> 0 | D12: =VLOOKUP(INPUTS!L9, TABLE!A4:R37, 3) -> 0 | E12: =VLOOKUP(INPUTS!L9, TABLE!A4:R37, 4) -> 0 | F12: =IF(E12=0,0,INPUTS!L9/E12) -> 0 | G12: =E12*INPUTS!J22 -> 0 | H12: =VLOOKUP(INPUTS!L9, TABLE!A4:R37, 5) -> 0 | I12: =VLOOKUP(INPUTS!L9, TABLE!A4:R37, 10) -> 0 | J12: =VLOOKUP(INPUTS!L9, TABLE!A4:R37, 6) -> 0 | K12: =INPUTS!$J$17*J12 -> 0 | L12: =I12*INPUTS!$J$18 -> 0 | M12: =H12*INPUTS!$J$19/100 -> 0 | N12: =H12*INPUTS!$J$20/100 -> 0 | O12: =E12*INPUTS!J22*INPUTS!J24*INPUTS!J25 -> 0 | P12: =O12*INPUTS!$J$28/1000 -> 0 | Q12: =O12/1000*INPUTS!J29 -> 0 | R12: =O12*INPUTS!J30/1000 -> 0 | S12: =O12*8.33*1.2*INPUTS!$J$31/100000*INPUTS!$J$32 -> 0 | V12: =SUM((INPUTS!L9*70)/3960)/0.8 -> 0 | W12: =SUM(V12*0.746)*INPUTS!$J$34*24*INPUTS!$J$33*0.512 -> 0
A13: =INPUTS!H10 -> 0 | B13: =INPUTS!L10 -> 0 | C13: =VLOOKUP(INPUTS!L10, TABLE!A4:R37, 2) -> 0 | D13: =VLOOKUP(INPUTS!L10, TABLE!A4:R37, 3) -> 0 | E13: =VLOOKUP(INPUTS!L10, TABLE!A4:R37, 4) -> 0 | F13: =IF(E13=0,0,INPUTS!L10/E13) -> 0 | G13: =E13*INPUTS!J22 -> 0 | H13: =VLOOKUP(INPUTS!L10, TABLE!A4:R37, 5) -> 0 | I13: =VLOOKUP(INPUTS!L10, TABLE!A4:R37, 10) -> 0 | J13: =VLOOKUP(INPUTS!L10, TABLE!A4:R37, 6) -> 0 | K13: =INPUTS!$J$17*J13 -> 0 | L13: =I13*INPUTS!$J$18 -> 0 | M13: =H13*INPUTS!$J$19/100 -> 0 | N13: =H13*INPUTS!$J$20/100 -> 0 | O13: =E13*INPUTS!J22*INPUTS!J24*INPUTS!J25 -> 0 | P13: =O13*INPUTS!$J$28/1000 -> 0 | Q13: =O13/1000*INPUTS!J29 -> 0 | R13: =O13*INPUTS!J30/1000 -> 0 | S13: =O13*8.33*1.2*INPUTS!$J$31/100000*INPUTS!$J$32 -> 0 | V13: =SUM((INPUTS!L10*70)/3960)/0.8 -> 0 | W13: =SUM(V13*0.746)*INPUTS!$J$34*24*INPUTS!$J$33*0.512 -> 0
A14: =INPUTS!H11 -> 0 | B14: =INPUTS!L11 -> 0 | C14: =VLOOKUP(INPUTS!L11, TABLE!A4:R37, 2) -> 0 | D14: =VLOOKUP(INPUTS!L11, TABLE!A4:R37, 3) -> 0 | E14: =VLOOKUP(INPUTS!L11, TABLE!A4:R37, 4) -> 0 | F14: =IF(E14=0,0,INPUTS!L11/E14) -> 0 | G14: =E14*INPUTS!J22 -> 0 | H14: =VLOOKUP(INPUTS!L11, TABLE!A4:R37, 5) -> 0 | I14: =VLOOKUP(INPUTS!L11, TABLE!A4:R37, 10) -> 0 | J14: =VLOOKUP(INPUTS!L11, TABLE!A4:R37, 6) -> 0 | K14: =INPUTS!$J$17*J14 -> 0 | L14: =I14*INPUTS!$J$18 -> 0 | M14: =H14*INPUTS!$J$19/100 -> 0 | N14: =H14*INPUTS!$J$20/100 -> 0 | O14: =E14*INPUTS!J22*INPUTS!J24*INPUTS!J25 -> 0 | P14: =O14*INPUTS!$J$28/1000 -> 0 | Q14: =O14/1000*INPUTS!J29 -> 0 | R14: =O14*INPUTS!J30/1000 -> 0 | S14: =O14*8.33*1.2*INPUTS!$J$31/100000*INPUTS!$J$32 -> 0 | V14: =SUM((INPUTS!L11*70)/3960)/0.8 -> 0 | W14: =SUM(V14*0.746)*INPUTS!$J$34*24*INPUTS!$J$33*0.512 -> 0
A15: =INPUTS!H12 -> 0 | B15: =INPUTS!L12 -> 0 | C15: =VLOOKUP(INPUTS!L12, TABLE!A4:R37, 2) -> 0 | D15: =VLOOKUP(INPUTS!L12, TABLE!A4:R37, 3) -> 0 | E15: =VLOOKUP(INPUTS!L12, TABLE!A4:R37, 4) -> 0 | F15: =IF(E15=0,0,INPUTS!L12/E15) -> 0 | G15: =E15*INPUTS!J22 -> 0 | H15: =VLOOKUP(INPUTS!L12, TABLE!A4:R37, 5) -> 0 | I15: =VLOOKUP(INPUTS!L12, TABLE!A4:R37, 10) -> 0 | J15: =VLOOKUP(INPUTS!L12, TABLE!A4:R37, 6) -> 0 | K15: =INPUTS!$J$17*J15 -> 0 | L15: =I15*INPUTS!$J$18 -> 0 | M15: =H15*INPUTS!$J$19/100 -> 0 | N15: =H15*INPUTS!$J$20/100 -> 0 | O15: =E15*INPUTS!J22*INPUTS!J24*INPUTS!J25 -> 0 | P15: =O15*INPUTS!$J$28/1000 -> 0 | Q15: =O15/1000*INPUTS!J29 -> 0 | R15: =O15*INPUTS!J30/1000 -> 0 | S15: =O15*8.33*1.2*INPUTS!$J$31/100000*INPUTS!$J$32 -> 0 | V15: =SUM((INPUTS!L12*70)/3960)/0.8 -> 0 | W15: =SUM(V15*0.746)*INPUTS!$J$34*24*INPUTS!$J$33*0.512 -> 0
A16: =INPUTS!H13 -> 0 | B16: =INPUTS!L13 -> 0 | C16: =VLOOKUP(INPUTS!L13, TABLE!A4:R37, 2) -> 0 | D16: =VLOOKUP(INPUTS!L13, TABLE!A4:R37, 3) -> 0 | E16: =VLOOKUP(INPUTS!L13, TABLE!A4:R37, 4) -> 0 | F16: =IF(E16=0,0,INPUTS!L13/E16) -> 0 | G16: =E16*INPUTS!J22 -> 0 | H16: =VLOOKUP(INPUTS!L13, TABLE!A4:R37, 5) -> 0 | I16: =VLOOKUP(INPUTS!L13, TABLE!A4:R37, 10) -> 0 | J16: =VLOOKUP(INPUTS!L13, TABLE!A4:R37, 6) -> 0 | K16: =INPUTS!$J$17*J16 -> 0 | L16: =I16*INPUTS!$J$18 -> 0 | M16: =H16*INPUTS!$J$19/100 -> 0 | N16: =H16*INPUTS!$J$20/100 -> 0 | O16: =E16*INPUTS!J22*INPUTS!J24*INPUTS!J25 -> 0 | P16: =O16*INPUTS!$J$28/1000 -> 0 | Q16: =O16/1000*INPUTS!J29 -> 0 | R16: =O16*INPUTS!J30/1000 -> 0 | S16: =O16*8.33*1.2*INPUTS!$J$31/100000*INPUTS!$J$32 -> 0 | V16: =SUM((INPUTS!L13*70)/3960)/0.8 -> 0 | W16: =SUM(V16*0.746)*INPUTS!$J$34*24*INPUTS!$J$33*0.512 -> 0
A17: TOTALS | B17: =SUM(B7:B14) -> 0 | C17: =SUM(C7:C14) -> 0 | E17: =SUM(E7:E14) -> 0 | G17: =SUM(G7:G14) -> 0 | H17: =SUM(H7:H14) -> 0 | I17: =SUM(I7:I14) -> 0 | J17: =SUM(J7:J14) -> 0 | K17: =SUM(K7:K14) -> 0 | L17: =SUM(L7:L14) -> 0 | M17: =SUM(M7:M14) -> 0 | N17: =SUM(N7:N14) -> 0 | ... S17: =SUM(S7:S14) -> 0 | V17: =SUM(V7:V14) -> 0 | W17: =SUM(W7:W14) -> 0
A19: DEFENDER FILTER CAPITAL & OPERATING COSTS
A20: POOL DATA | C20: DEFENDER MEDIA FILTER DATA | I20: CAPITAL COSTS | O20: ANNUAL OPERATING COSTS * DEFENDER FILTER
A21: Pool Description | B21: Flow (gpm) | C21: Qty | D21: NB Model # | E21: Filter Surface Area (sf) | F21: Filtration Rate (gpm/sf) | G21: Tank Volume (gal) | H21: Total Media Wt (lb) | I21: Equipment Purchase Price | J21: MECHANICAL SPACE | N21: Perlite Media Cost | O21: FILTER BACKWASH | T21: PERLITE | V21: PUMP DATA
J22: Footprint (sf) | K22: Cost | O22: Volume (gal) (NOTE 1) | P22: Potable Water | Q22: Sewer Discharge | R22: Make-up Water Chem | S22: Make-up Water Heat | T22: Total Filter Recoat (lb) | U22: Total Perlite Cost (lb) | V22: Brake HP Req'd @ 55'TDH | W22: Electrical Cost w/VFD
A23: =INPUTS!B9 -> 0 | B23: =INPUTS!E9 -> 0 | C23: =VLOOKUP(INPUTS!E9, TABLE!A4:R37, 11) -> 0 | D23: =VLOOKUP(INPUTS!E9, TABLE!A4:R37, 12) -> 0 | E23: =VLOOKUP(INPUTS!E9, TABLE!A4:R37, 13) -> 0 | F23: =IF(E23=0,0,B23/E23) -> 0 | G23: =VLOOKUP(INPUTS!E9, TABLE!A4:R37, 14) -> 0 | H23: =0.075*E23 -> 0 | I23: =VLOOKUP(INPUTS!E9, TABLE!A4:R37, 18) -> 0 | J23: =VLOOKUP(INPUTS!E9, TABLE!A4:R37, 15) -> 0 | K23: =INPUTS!$J$17*J23 -> 0 | N23: =H23*INPUTS!$J$21 -> 0 | O23: =IF(INPUTS!D9="I",(G23*2*INPUTS!J27+0.1*O7),(G23*2*INPUTS!J27)) -> 0 | P23: =O23*INPUTS!$J$28/1000 -> 0 | Q23: =O23*INPUTS!J29/1000 -> 0 | R23: =O23*0.003 -> 0 | S23: =O23*8.33*1.2*INPUTS!$J$31/100000*INPUTS!$J$32 -> 0 | T23: =H23*INPUTS!$J$27 -> 0 | U23: =T23*INPUTS!$J$21 -> 0 | V23: =SUM((B23*55)/3960)/0.8 -> 0 | W23: =(SUM(V23*0.746)*INPUTS!$J$34*24*INPUTS!$J$33)*0.512 -> 0
A24: =INPUTS!B10 -> 0 | B24: =INPUTS!E10 -> 0 | C24: =VLOOKUP(INPUTS!E10, TABLE!A4:R37, 11) -> 0 | D24: =VLOOKUP(INPUTS!E10, TABLE!A4:R37, 12) -> 0 | E24: =VLOOKUP(INPUTS!E10, TABLE!A4:R37, 13) -> 0 | F24: =IF(E24=0,0,B24/E24) -> 0 | G24: =VLOOKUP(INPUTS!E10, TABLE!A4:R37, 14) -> 0 | H24: =0.075*E24 -> 0 | I24: =VLOOKUP(INPUTS!E10, TABLE!A4:R37, 18) -> 0 | J24: =VLOOKUP(INPUTS!E10, TABLE!A4:R37, 15) -> 0 | K24: =INPUTS!$J$17*J24 -> 0 | N24: =H24*INPUTS!$J$21 -> 0 | O24: =IF(INPUTS!D10="I",(G24*2*INPUTS!J27+0.1*O8),(G24*2*INPUTS!J27)) -> 0 | P24: =O24*INPUTS!$J$28/1000 -> 0 | Q24: =O24*INPUTS!J29/1000 -> 0 | R24: =O24*0.003 -> 0 | S24: =O24*8.33*1.2*INPUTS!$J$31/100000*INPUTS!$J$32 -> 0 | T24: =H24*INPUTS!$J$27 -> 0 | U24: =T24*INPUTS!$J$21 -> 0 | V24: =SUM((B24*55)/3960)/0.8 -> 0 | W24: =(SUM(V24*0.746)*INPUTS!$J$34*24*INPUTS!$J$33)*0.512 -> 0
A25: =INPUTS!B11 -> 0 | B25: =INPUTS!E11 -> 0 | C25: =VLOOKUP(INPUTS!E11, TABLE!A4:R37, 11) -> 0 | D25: =VLOOKUP(INPUTS!E11, TABLE!A4:R37, 12) -> 0 | E25: =VLOOKUP(INPUTS!E11, TABLE!A4:R37, 13) -> 0 | F25: =IF(E25=0,0,B25/E25) -> 0 | G25: =VLOOKUP(INPUTS!E11, TABLE!A4:R37, 14) -> 0 | H25: =0.075*E25 -> 0 | I25: =VLOOKUP(INPUTS!E11, TABLE!A4:R37, 18) -> 0 | J25: =VLOOKUP(INPUTS!E11, TABLE!A4:R37, 15) -> 0 | K25: =INPUTS!$J$17*J25 -> 0 | N25: =H25*INPUTS!$J$21 -> 0 | O25: =IF(INPUTS!D11="I",(G25*2*INPUTS!J27+0.1*O9),(G25*2*INPUTS!J27)) -> 0 | P25: =O25*INPUTS!$J$28/1000 -> 0 | Q25: =O25*INPUTS!J29/1000 -> 0 | R25: =O25*0.003 -> 0 | S25: =O25*8.33*1.2*INPUTS!$J$31/100000*INPUTS!$J$32 -> 0 | T25: =H25*INPUTS!$J$27 -> 0 | U25: =T25*INPUTS!$J$21 -> 0 | V25: =SUM((B25*55)/3960)/0.8 -> 0 | W25: =(SUM(V25*0.746)*INPUTS!$J$34*24*INPUTS!$J$33)*0.512 -> 0
A26: =INPUTS!B12 -> 0 | B26: =INPUTS!E12 -> 0 | C26: =VLOOKUP(INPUTS!E12, TABLE!A4:R37, 11) -> 0 | D26: =VLOOKUP(INPUTS!E12, TABLE!A4:R37, 12) -> 0 | E26: =VLOOKUP(INPUTS!E12, TABLE!A4:R37, 13) -> 0 | F26: =IF(E26=0,0,B26/E26) -> 0 | G26: =VLOOKUP(INPUTS!E12, TABLE!A4:R37, 14) -> 0 | H26: =0.075*E26 -> 0 | I26: =VLOOKUP(INPUTS!E12, TABLE!A4:R37, 18) -> 0 | J26: =VLOOKUP(INPUTS!E12, TABLE!A4:R37, 15) -> 0 | K26: =INPUTS!$J$17*J26 -> 0 | N26: =H26*INPUTS!$J$21 -> 0 | O26: =IF(INPUTS!D12="I",(G26*2*INPUTS!J27+0.1*O10),(G26*2*INPUTS!J27)) -> 0 | P26: =O26*INPUTS!$J$28/1000 -> 0 | Q26: =O26*INPUTS!J29/1000 -> 0 | R26: =O26*0.003 -> 0 | S26: =O26*8.33*1.2*INPUTS!$J$31/100000*INPUTS!$J$32 -> 0 | T26: =H26*INPUTS!$J$27 -> 0 | U26: =T26*INPUTS!$J$21 -> 0 | V26: =SUM((B26*55)/3960)/0.8 -> 0 | W26: =(SUM(V26*0.746)*INPUTS!$J$34*24*INPUTS!$J$33)*0.512 -> 0
A27: =INPUTS!B13 -> 0 | B27: =INPUTS!E13 -> 0 | C27: =VLOOKUP(INPUTS!E13, TABLE!A4:R37, 11) -> 0 | D27: =VLOOKUP(INPUTS!E13, TABLE!A4:R37, 12) -> 0 | E27: =VLOOKUP(INPUTS!E13, TABLE!A4:R37, 13) -> 0 | F27: =IF(E27=0,0,B27/E27) -> 0 | G27: =VLOOKUP(INPUTS!E13, TABLE!A4:R37, 14) -> 0 | H27: =0.075*E27 -> 0 | I27: =VLOOKUP(INPUTS!E13, TABLE!A4:R37, 18) -> 0 | J27: =VLOOKUP(INPUTS!E13, TABLE!A4:R37, 15) -> 0 | K27: =INPUTS!$J$17*J27 -> 0 | N27: =H27*INPUTS!$J$21 -> 0 | O27: =IF(INPUTS!D13="I",(G27*2*INPUTS!J27+0.1*O11),(G27*2*INPUTS!J27)) -> 0 | P27: =O27*INPUTS!$J$28/1000 -> 0 | Q27: =O27*INPUTS!J29/1000 -> 0 | R27: =O27*0.003 -> 0 | S27: =O27*8.33*1.2*INPUTS!$J$31/100000*INPUTS!$J$32 -> 0 | T27: =H27*INPUTS!$J$27 -> 0 | U27: =T27*INPUTS!$J$21 -> 0 | V27: =SUM((B27*55)/3960)/0.8 -> 0 | W27: =(SUM(V27*0.746)*INPUTS!$J$34*24*INPUTS!$J$33)*0.512 -> 0
A28: =INPUTS!H9 -> 0 | B28: =INPUTS!L9 -> 0 | C28: =VLOOKUP(INPUTS!L9, TABLE!A4:R37, 11) -> 0 | D28: =VLOOKUP(INPUTS!L9, TABLE!A4:R37, 12) -> 0 | E28: =VLOOKUP(INPUTS!L9, TABLE!A4:R37, 13) -> 0 | F28: =IF(E28=0,0,B28/E28) -> 0 | G28: =VLOOKUP(INPUTS!L9, TABLE!A4:R37, 14) -> 0 | H28: =0.075*E28 -> 0 | I28: =VLOOKUP(INPUTS!L9, TABLE!A4:R37, 18) -> 0 | J28: =VLOOKUP(INPUTS!L9, TABLE!A4:R37, 15) -> 0 | K28: =INPUTS!$J$17*J28 -> 0 | N28: =H28*INPUTS!$J$21 -> 0 | O28: =IF(INPUTS!K9="I",(G28*2*INPUTS!J27+0.1*O12),(G28*2*INPUTS!J27)) -> 0 | P28: =O28*INPUTS!$J$28/1000 -> 0 | Q28: =O28*INPUTS!J29/1000 -> 0 | R28: =O28*0.003 -> 0 | S28: =O28*8.33*1.2*INPUTS!$J$31/100000*INPUTS!$J$32 -> 0 | T28: =H28*INPUTS!$J$27 -> 0 | U28: =T28*INPUTS!$J$21 -> 0 | V28: =SUM((B28*55)/3960)/0.8 -> 0 | W28: =(SUM(V28*0.746)*INPUTS!$J$34*24*INPUTS!$J$33)*0.512 -> 0
A29: =INPUTS!H10 -> 0 | B29: =INPUTS!L10 -> 0 | C29: =VLOOKUP(INPUTS!L10, TABLE!A4:R37, 11) -> 0 | D29: =VLOOKUP(INPUTS!L10, TABLE!A4:R37, 12) -> 0 | E29: =VLOOKUP(INPUTS!L10, TABLE!A4:R37, 13) -> 0 | F29: =IF(E29=0,0,B29/E29) -> 0 | G29: =VLOOKUP(INPUTS!L10, TABLE!A4:R37, 14) -> 0 | H29: =0.075*E29 -> 0 | I29: =VLOOKUP(INPUTS!L10, TABLE!A4:R37, 18) -> 0 | J29: =VLOOKUP(INPUTS!L10, TABLE!A4:R37, 15) -> 0 | K29: =INPUTS!$J$17*J29 -> 0 | N29: =H29*INPUTS!$J$21 -> 0 | O29: =IF(INPUTS!K10="I",(G29*2*INPUTS!J27+0.1*O13),(G29*2*INPUTS!J27)) -> 0 | P29: =O29*INPUTS!$J$28/1000 -> 0 | Q29: =O29*INPUTS!J29/1000 -> 0 | R29: =O29*0.003 -> 0 | S29: =O29*8.33*1.2*INPUTS!$J$31/100000*INPUTS!$J$32 -> 0 | T29: =H29*INPUTS!$J$27 -> 0 | U29: =T29*INPUTS!$J$21 -> 0 | V29: =SUM((B29*55)/3960)/0.8 -> 0 | W29: =(SUM(V29*0.746)*INPUTS!$J$34*24*INPUTS!$J$33)*0.512 -> 0
A30: =INPUTS!H11 -> 0 | B30: =INPUTS!L11 -> 0 | C30: =VLOOKUP(INPUTS!L11, TABLE!A4:R37, 11) -> 0 | D30: =VLOOKUP(INPUTS!L11, TABLE!A4:R37, 12) -> 0 | E30: =VLOOKUP(INPUTS!L11, TABLE!A4:R37, 13) -> 0 | F30: =IF(E30=0,0,B30/E30) -> 0 | G30: =VLOOKUP(INPUTS!L11, TABLE!A4:R37, 14) -> 0 | H30: =0.075*E30 -> 0 | I30: =VLOOKUP(INPUTS!L11, TABLE!A4:R37, 18) -> 0 | J30: =VLOOKUP(INPUTS!L11, TABLE!A4:R37, 15) -> 0 | K30: =INPUTS!$J$17*J30 -> 0 | N30: =H30*INPUTS!$J$21 -> 0 | O30: =IF(INPUTS!K11="I",(G30*2*INPUTS!J27+0.1*O14),(G30*2*INPUTS!J27)) -> 0 | P30: =O30*INPUTS!$J$28/1000 -> 0 | Q30: =O30*INPUTS!J29/1000 -> 0 | R30: =O30*0.003 -> 0 | S30: =O30*8.33*1.2*INPUTS!$J$31/100000*INPUTS!$J$32 -> 0 | T30: =H30*INPUTS!$J$27 -> 0 | U30: =T30*INPUTS!$J$21 -> 0 | V30: =SUM((B30*55)/3960)/0.8 -> 0 | W30: =(SUM(V30*0.746)*INPUTS!$J$34*24*INPUTS!$J$33)*0.512 -> 0
A31: =INPUTS!H12 -> 0 | B31: =INPUTS!L12 -> 0 | C31: =VLOOKUP(INPUTS!L12, TABLE!A4:R37, 11) -> 0 | D31: =VLOOKUP(INPUTS!L12, TABLE!A4:R37, 12) -> 0 | E31: =VLOOKUP(INPUTS!L12, TABLE!A4:R37, 13) -> 0 | F31: =IF(E31=0,0,B31/E31) -> 0 | G31: =VLOOKUP(INPUTS!L12, TABLE!A4:R37, 14) -> 0 | H31: =0.075*E31 -> 0 | I31: =VLOOKUP(INPUTS!L12, TABLE!A4:R37, 18) -> 0 | J31: =VLOOKUP(INPUTS!L12, TABLE!A4:R37, 15) -> 0 | K31: =INPUTS!$J$17*J31 -> 0 | N31: =H31*INPUTS!$J$21 -> 0 | O31: =IF(INPUTS!K12="I",(G31*2*INPUTS!J27+0.1*O15),(G31*2*INPUTS!J27)) -> 0 | P31: =O31*INPUTS!$J$28/1000 -> 0 | Q31: =O31*INPUTS!J29/1000 -> 0 | R31: =O31*0.003 -> 0 | S31: =O31*8.33*1.2*INPUTS!$J$31/100000*INPUTS!$J$32 -> 0 | T31: =H31*INPUTS!$J$27 -> 0 | U31: =T31*INPUTS!$J$21 -> 0 | V31: =SUM((B31*55)/3960)/0.8 -> 0 | W31: =(SUM(V31*0.746)*INPUTS!$J$34*24*INPUTS!$J$33)*0.512 -> 0
A32: =INPUTS!H13 -> 0 | B32: =INPUTS!L13 -> 0 | C32: =VLOOKUP(INPUTS!L13, TABLE!A4:R37, 11) -> 0 | D32: =VLOOKUP(INPUTS!L13, TABLE!A4:R37, 12) -> 0 | E32: =VLOOKUP(INPUTS!L13, TABLE!A4:R37, 13) -> 0 | F32: =IF(E32=0,0,B32/E32) -> 0 | G32: =VLOOKUP(INPUTS!L13, TABLE!A4:R37, 14) -> 0 | H32: =0.075*E32 -> 0 | I32: =VLOOKUP(INPUTS!L13, TABLE!A4:R37, 18) -> 0 | J32: =VLOOKUP(INPUTS!L13, TABLE!A4:R37, 15) -> 0 | K32: =INPUTS!$J$17*J32 -> 0 | N32: =H32*INPUTS!$J$21 -> 0 | O32: =IF(INPUTS!K13="I",(G32*2*INPUTS!J27+0.1*O16),(G32*2*INPUTS!J27)) -> 0 | P32: =O32*INPUTS!$J$28/1000 -> 0 | Q32: =O32*INPUTS!J29/1000 -> 0 | R32: =O32*0.003 -> 0 | S32: =O32*8.33*1.2*INPUTS!$J$31/100000*INPUTS!$J$32 -> 0 | T32: =H32*INPUTS!$J$27 -> 0 | U32: =T32*INPUTS!$J$21 -> 0 | V32: =SUM((B32*55)/3960)/0.8 -> 0 | W32: =(SUM(V32*0.746)*INPUTS!$J$34*24*INPUTS!$J$33)*0.512 -> 0
A33: Compressors | C33: =INPUTS!J36 -> 1 | I33: =C33*TABLE!R39 -> 1379.9541
A34: Defender Tool Kits | C34: =INPUTS!J37 -> 1 | I34: =C34*TABLE!R40 -> 330.04743
A35: TOTALS | B35: =SUM(B23:B30) -> 0 | C35: =SUM(C23:C30) -> 0 | E35: =SUM(E23:E30) -> 0 | G35: =SUM(G23:G30) -> 0 | H35: =SUM(H23:H30) -> 0 | I35: =SUM(I23:I34) -> 1710.0016 | J35: =SUM(J23:J30) -> 0 | K35: =SUM(K23:K30) -> 0 | N35: =SUM(N23:N30) -> 0 | O35: =SUM(O23:O30) -> 0 | P35: =SUM(P23:P30) -> 0 | Q35: =SUM(Q23:Q30) -> 0 | R35: =SUM(R23:R30) -> 0 | S35: =SUM(S23:S30) -> 0 | T35: =SUM(T23:T30) -> 0 | U35: =SUM(U23:U30) -> 0 | ... W35: =SUM(W23:W30) -> 0
E37: PROJECT NAME: | G37: =INPUTS!C3 -> 0 | R37: PREPARED BY: | U37: =INPUTS!I5 -> 0
E38: LOCATION: | G38: =INPUTS!C4 -> 0 | R38: PHONE: | U38: 800-832-8002
E39: PREPARED FOR: | G39: =INPUTS!I4 -> 0 | R39: FAX: | U39: 401-821-7129
E40: DATE: | G40: =INPUTS!I3 -> 0 | R40: WEBSITE: | U40: www.DefenderFilter.com

Sheet GRAPH DATA
A1: SAND FILTER | B1: LIFECYCLE YEAR
B2: 1 | C2: =+B2+1 -> 2 | D2: =+C2+1 -> 3 | E2: =+D2+1 -> 4 | F2: =+E2+1 -> 5 | G2: =+F2+1 -> 6 | H2: =+G2+1 -> 7 | I2: =+H2+1 -> 8 | J2: =+I2+1 -> 9 | K2: =+J2+1 -> 10
A3: FILTER | B3: =SUMMARY!$C$9 -> 0 | C3: =B3 -> 0 | D3: =C3 -> 0 | E3: =D3 -> 0 | F3: =E3 -> 0 | G3: =F3 -> 0 | H3: =G3 -> 0 | I3: =H3 -> 0 | J3: =I3 -> 0 | K3: =J3 -> 0
A4: ELECTRICAL | B4: =SUMMARY!C13 -> 0 | C4: =B4+(B4*(POWER((1+INPUTS!J35),B2))) -> 0 | D4: =C4+(B4*(POWER((1+INPUTS!J35),C2))) -> 0 | E4: =D4+(B4*(POWER((1+INPUTS!J35),D2))) -> 0 | F4: =E4+(B4*(POWER((1+INPUTS!J35),E2))) -> 0 | G4: =F4+(B4*(POWER((1+INPUTS!J35),F2))) -> 0 | H4: =G4+(B4*(POWER((1+INPUTS!J35),G2))) -> 0 | I4: =H4+(B4*(POWER((1+INPUTS!J35),H2))) -> 0 | J4: =I4+(B4*(POWER((1+INPUTS!J35),I2))) -> 0 | K4: =J4+(B4*(POWER((1+INPUTS!J35),J2))) -> 0
A5: POTABLE WATER FEE | B5: =SUMMARY!C14 -> 0 | C5: =B5+(B5*(POWER((1+INPUTS!J35),B2))) -> 0 | D5: =C5+(B5*(POWER((1+INPUTS!J35),C2))) -> 0 | E5: =D5+(B5*(POWER((1+INPUTS!J35),D2))) -> 0 | F5: =E5+(B5*(POWER((1+INPUTS!J35),E2))) -> 0 | G5: =F5+(B5*(POWER((1+INPUTS!J35),F2))) -> 0 | H5: =G5+(B5*(POWER((1+INPUTS!J35),G2))) -> 0 | I5: =H5+(B5*(POWER((1+INPUTS!J35),H2))) -> 0 | J5: =I5+(B5*(POWER((1+INPUTS!J35),I2))) -> 0 | K5: =J5+(B5*(POWER((1+INPUTS!J35),J2))) -> 0
A6: MAKE-UP - CHEMICALS | B6: =SUMMARY!C15 -> 0 | C6: =B6+(B6*(POWER((1+INPUTS!J35),B2))) -> 0 | D6: =C6+(B6*(POWER((1+INPUTS!J35),C2))) -> 0 | E6: =D6+(B6*(POWER((1+INPUTS!J35),D2))) -> 0 | F6: =E6+(B6*(POWER((1+INPUTS!J35),E2))) -> 0 | G6: =F6+(B6*(POWER((1+INPUTS!J35),F2))) -> 0 | H6: =G6+(B6*(POWER((1+INPUTS!J35),G2))) -> 0 | I6: =H6+(B6*(POWER((1+INPUTS!J35),H2))) -> 0 | J6: =I6+(B6*(POWER((1+INPUTS!J35),I2))) -> 0 | K6: =J6+(B6*(POWER((1+INPUTS!J35),J2))) -> 0
A7: MAKE-UP - HEAT | B7: =SUMMARY!C16 -> 0 | C7: =B7+(B7*(POWER((1+INPUTS!J35),B2))) -> 0 | D7: =C7+(B7*(POWER((1+INPUTS!J35),C2))) -> 0 | E7: =D7+(B7*(POWER((1+INPUTS!J35),D2))) -> 0 | F7: =E7+(B7*(POWER((1+INPUTS!J35),E2))) -> 0 | G7: =F7+(B7*(POWER((1+INPUTS!J35),F2))) -> 0 | H7: =G7+(B7*(POWER((1+INPUTS!J35),G2))) -> 0 | I7: =H7+(B7*(POWER((1+INPUTS!J35),H2))) -> 0 | J7: =I7+(B7*(POWER((1+INPUTS!J35),I2))) -> 0 | K7: =J7+(B7*(POWER((1+INPUTS!J35),J2))) -> 0
A8: SEWER FEE | B8: =SUMMARY!C17 -> 0 | C8: =B8+(B8*(POWER((1+INPUTS!J35),B2))) -> 0 | D8: =C8+(B8*(POWER((1+INPUTS!J35),C2))) -> 0 | E8: =D8+(B8*(POWER((1+INPUTS!J35),D2))) -> 0 | F8: =E8+(B8*(POWER((1+INPUTS!J35),E2))) -> 0 | G8: =F8+(B8*(POWER((1+INPUTS!J35),F2))) -> 0 | H8: =G8+(B8*(POWER((1+INPUTS!J35),G2))) -> 0 | I8: =H8+(B8*(POWER((1+INPUTS!J35),H2))) -> 0 | J8: =I8+(B8*(POWER((1+INPUTS!J35),I2))) -> 0 | K8: =J8+(B8*(POWER((1+INPUTS!J35),J2))) -> 0
A9: MEDIA PURCHASE | B9: =+SUMMARY!D3 -> 0 | C9: =B9+(B9*(POWER((1+INPUTS!J35),B2))) -> 0 | D9: =C9+(B9*(POWER((1+INPUTS!J35),C2))) -> 0 | E9: =D9+(B9*(POWER((1+INPUTS!J35),D2))) -> 0 | F9: =DETAIL!N17 -> 0 | G9: =F9+(B9*(POWER((1+INPUTS!J35),F2))) -> 0 | H9: =G9+(B9*(POWER((1+INPUTS!J35),G2))) -> 0 | I9: =H9+(B9*(POWER((1+INPUTS!J35),H2))) -> 0 | J9: =I9+(B9*(POWER((1+INPUTS!J35),I2))) -> 0 | K9: =J9+(B9*(POWER((1+INPUTS!J35),J2))) -> 0
A10: MEDIA LOADING | B10: 0 | C10: 0 | D10: 0 | E10: 0 | F10: =DETAIL!M17*(POWER((1+INPUTS!J35),'GRAPH DATA'!E2)) -> 0 | G10: =F10 -> 0 | H10: =G10 -> 0 | I10: =H10 -> 0 | J10: =I10 -> 0 | K10: =F10+DETAIL!M17*(POWER((1+INPUTS!J35),'GRAPH DATA'!J2)) -> 0
A11: CUMULATIVE EXPENSE | B11: =SUM(B3:B10) -> 0 | C11: =SUM(C3:C10) -> 0 | D11: =SUM(D3:D10) -> 0 | E11: =SUM(E3:E10) -> 0 | F11: =SUM(F3:F10) -> 0 | G11: =SUM(G3:G10) -> 0 | H11: =SUM(H3:H10) -> 0 | I11: =SUM(I3:I10) -> 0 | ... K11: =SUM(K3:K10) -> 0
A13: DEFENDER FILTER | B13: LIFECYCLE YEAR
B14: 1 | C14: =+B14+1 -> 2 | D14: =+C14+1 -> 3 | E14: =+D14+1 -> 4 | F14: =+E14+1 -> 5 | G14: =+F14+1 -> 6 | H14: =+G14+1 -> 7 | I14: =+H14+1 -> 8 | J14: =+I14+1 -> 9 | K14: =+J14+1 -> 10
A15: FILTER | B15: =+SUMMARY!D9 -> 1710.0016 | C15: =+B15 -> 1710.0016 | D15: =+C15 -> 1710.0016 | E15: =+D15 -> 1710.0016 | F15: =+E15 -> 1710.0016 | G15: =+F15 -> 1710.0016 | H15: =+G15 -> 1710.0016 | I15: =+H15 -> 1710.0016 | J15: =+I15 -> 1710.0016 | K15: =+J15 -> 1710.0016
A16: ELECTRICAL | B16: =SUMMARY!D13 -> 0 | C16: =B16+(B16*(POWER((1+INPUTS!J35),B14))) -> 0 | D16: =C16+(B16*(POWER((1+INPUTS!J35),C14))) -> 0 | E16: =D16+(B16*(POWER((1+INPUTS!J35),D14))) -> 0 | F16: =E16+(B16*(POWER((1+INPUTS!J35),E14))) -> 0 | G16: =F16+(B16*(POWER((1+INPUTS!J35),F14))) -> 0 | H16: =G16+(B16*(POWER((1+INPUTS!J35),G14))) -> 0 | I16: =H16+(B16*(POWER((1+INPUTS!J35),H14))) -> 0 | J16: =I16+(B16*(POWER((1+INPUTS!J35),I14))) -> 0 | K16: =J16+(B16*(POWER((1+INPUTS!J35),J14))) -> 0
A17: POTABLE WATER FEE | B17: =+SUMMARY!D14 -> 0 | C17: =B17+(B17*(POWER((1+INPUTS!J35),B14))) -> 0 | D17: =C17+(B17*(POWER((1+INPUTS!J35),C14))) -> 0 | E17: =D17+(B17*(POWER((1+INPUTS!J35),D14))) -> 0 | F17: =E17+(B17*(POWER((1+INPUTS!J35),E14))) -> 0 | G17: =F17+(B17*(POWER((1+INPUTS!J35),F14))) -> 0 | H17: =G17+(B17*(POWER((1+INPUTS!J35),G14))) -> 0 | I17: =H17+(B17*(POWER((1+INPUTS!J35),H14))) -> 0 | J17: =I17+(B17*(POWER((1+INPUTS!J35),I14))) -> 0 | K17: =J17+(B17*(POWER((1+INPUTS!J35),J14))) -> 0
A18: MAKE-UP - CHEMICALS | B18: =+SUMMARY!D15 -> 0 | C18: =B18+(B18*(POWER((1+INPUTS!J35),B14))) -> 0 | D18: =C18+(B18*(POWER((1+INPUTS!J35),C14))) -> 0 | E18: =D18+(B18*(POWER((1+INPUTS!J35),D14))) -> 0 | F18: =E18+(B18*(POWER((1+INPUTS!J35),E14))) -> 0 | G18: =F18+(B18*(POWER((1+INPUTS!J35),F14))) -> 0 | H18: =G18+(B18*(POWER((1+INPUTS!J35),G14))) -> 0 | I18: =H18+(B18*(POWER((1+INPUTS!J35),H14))) -> 0 | J18: =I18+(B18*(POWER((1+INPUTS!J35),I14))) -> 0 | K18: =J18+(B18*(POWER((1+INPUTS!J35),J14))) -> 0
A19: MAKE-UP - HEAT | B19: =+SUMMARY!D16 -> 0 | C19: =B19+(B19*(POWER((1+INPUTS!J35),B14))) -> 0 | D19: =C19+(B19*(POWER((1+INPUTS!J35),C14))) -> 0 | E19: =D19+(B19*(POWER((1+INPUTS!J35),D14))) -> 0 | F19: =E19+(B19*(POWER((1+INPUTS!J35),E14))) -> 0 | G19: =F19+(B19*(POWER((1+INPUTS!J35),F14))) -> 0 | H19: =G19+(B19*(POWER((1+INPUTS!J35),G14))) -> 0 | I19: =H19+(B19*(POWER((1+INPUTS!J35),H14))) -> 0 | J19: =I19+(B19*(POWER((1+INPUTS!J35),I14))) -> 0 | K19: =J19+(B19*(POWER((1+INPUTS!J35),J14))) -> 0
A20: SEWER FEE | B20: =+SUMMARY!D17 -> 0 | C20: =B20+(B20*(POWER((1+INPUTS!J35),B14))) -> 0 | D20: =C20+(B20*(POWER((1+INPUTS!J35),C14))) -> 0 | E20: =D20+(B20*(POWER((1+INPUTS!J35),D14))) -> 0 | F20: =E20+(B20*(POWER((1+INPUTS!J35),E14))) -> 0 | G20: =F20+(B20*(POWER((1+INPUTS!J35),F14))) -> 0 | H20: =G20+(B20*(POWER((1+INPUTS!J35),G14))) -> 0 | I20: =H20+(B20*(POWER((1+INPUTS!J35),H14))) -> 0 | J20: =I20+(B20*(POWER((1+INPUTS!J35),I14))) -> 0 | K20: =J20+(B20*(POWER((1+INPUTS!J35),J14))) -> 0
A21: MEDIA PURCHASE | B21: =+SUMMARY!D18 -> 0 | C21: =B21+(B21*(POWER((1+INPUTS!J35),B14))) -> 0 | D21: =C21+(B21*(POWER((1+INPUTS!J35),C14))) -> 0 | E21: =D21+(B21*(POWER((1+INPUTS!J35),D14))) -> 0 | F21: =E21+(B21*(POWER((1+INPUTS!J35),E14))) -> 0 | G21: =F21+(B21*(POWER((1+INPUTS!J35),F14))) -> 0 | H21: =G21+(B21*(POWER((1+INPUTS!J35),G14))) -> 0 | I21: =H21+(B21*(POWER((1+INPUTS!J35),H14))) -> 0 | J21: =I21+(B21*(POWER((1+INPUTS!J35),I14))) -> 0 | K21: =J21+(B21*(POWER((1+INPUTS!J35),J14))) -> 0
A22: MEDIA LOADING | B22: 0 | C22: =B22+(B22*(POWER((1+INPUTS!J39),B17))) -> 0 | D22: =C22+(B22*(POWER((1+INPUTS!J39),C17))) -> 0 | E22: =D22+(B22*(POWER((1+INPUTS!J39),D17))) -> 0 | F22: =E22+(B22*(POWER((1+INPUTS!J39),E17))) -> 0 | G22: =F22+(B22*(POWER((1+INPUTS!J39),F17))) -> 0 | H22: =G22+(B22*(POWER((1+INPUTS!J39),G17))) -> 0 | I22: =H22+(B22*(POWER((1+INPUTS!J39),H17))) -> 0 | J22: =I22+(B22*(POWER((1+INPUTS!J39),I17))) -> 0 | K22: =J22+(B22*(POWER((1+INPUTS!J39),J17))) -> 0
A23: CUMULATIVE EXPENSE | B23: =SUM(B15:B22) -> 1710.0016 | C23: =SUM(C15:C22) -> 1710.0016 | D23: =SUM(D15:D22) -> 1710.0016 | E23: =SUM(E15:E22) -> 1710.0016 | F23: =SUM(F15:F22) -> 1710.0016 | G23: =SUM(G15:G22) -> 1710.0016 | H23: =SUM(H15:H22) -> 1710.0016 | I23: =SUM(I15:I22) -> 1710.0016 | ... K23: =SUM(K15:K22) -> 1710.0016
A25: GRAPH ADJUSTED ROI CALCULATION
A26: VARIANCE | B26: FILTER | C26: OE | D26: TOTAL | E26: FILTER | F26: OE | G26: TOTAL | H26: MONTH
A27: =G27-D27 -> 1710.0016 | B27: =B28 -> 0 | C27: =C28 -> 0 | D27: =D28+C27 -> 0 | E27: =E28 -> 1710.0016 | F27: =F28 -> 0 | G27: =G28+F27 -> 1710.0016 | H27: 240
A28: =G28-D28 -> 1710.0016 | B28: =B29 -> 0 | C28: =C29 -> 0 | D28: =D29+C28 -> 0 | E28: =E29 -> 1710.0016 | F28: =F29 -> 0 | G28: =G29+F28 -> 1710.0016 | H28: 239
A29: =G29-D29 -> 1710.0016 | B29: =B30 -> 0 | C29: =C30 -> 0 | D29: =D30+C29 -> 0 | E29: =E30 -> 1710.0016 | F29: =F30 -> 0 | G29: =G30+F29 -> 1710.0016 | H29: 238
A30: =G30-D30 -> 1710.0016 | B30: =B31 -> 0 | C30: =C31 -> 0 | D30: =D31+C30 -> 0 | E30: =E31 -> 1710.0016 | F30: =F31 -> 0 | G30: =G31+F30 -> 1710.0016 | H30: 237
A31: =G31-D31 -> 1710.0016 | B31: =B32 -> 0 | C31: =C32 -> 0 | D31: =D32+C31 -> 0 | E31: =E32 -> 1710.0016 | F31: =F32 -> 0 | G31: =G32+F31 -> 1710.0016 | H31: 236
A32: =G32-D32 -> 1710.0016 | B32: =B33 -> 0 | C32: =C33 -> 0 | D32: =D33+C32 -> 0 | E32: =E33 -> 1710.0016 | F32: =F33 -> 0 | G32: =G33+F32 -> 1710.0016 | H32: 235
A33: =G33-D33 -> 1710.0016 | B33: =B34 -> 0 | C33: =C34 -> 0 | D33: =D34+C33 -> 0 | E33: =E34 -> 1710.0016 | F33: =F34 -> 0 | G33: =G34+F33 -> 1710.0016 | H33: 234
A34: =G34-D34 -> 1710.0016 | B34: =B35 -> 0 | C34: =C35 -> 0 | D34: =D35+C34 -> 0 | E34: =E35 -> 1710.0016 | F34: =F35 -> 0 | G34: =G35+F34 -> 1710.0016 | H34: 233
A35: =G35-D35 -> 1710.0016 | B35: =B36 -> 0 | C35: =C36 -> 0 | D35: =D36+C35 -> 0 | E35: =E36 -> 1710.0016 | F35: =F36 -> 0 | G35: =G36+F35 -> 1710.0016 | H35: 232
A36: =G36-D36 -> 1710.0016 | B36: =B37 -> 0 | C36: =C37 -> 0 | D36: =D37+C36 -> 0 | E36: =E37 -> 1710.0016 | F36: =F37 -> 0 | G36: =G37+F36 -> 1710.0016 | H36: 231
A37: =G37-D37 -> 1710.0016 | B37: =B38 -> 0 | C37: =C38 -> 0 | D37: =D38+C37 -> 0 | E37: =E38 -> 1710.0016 | F37: =F38 -> 0 | G37: =G38+F37 -> 1710.0016 | H37: 230
A38: =G38-D38 -> 1710.0016 | B38: =B39 -> 0 | C38: =C39*1.07 -> 0 | D38: =D39+C38 -> 0 | E38: =E39 -> 1710.0016 | F38: =F39*1.07 -> 0 | G38: =G39+F38 -> 1710.0016 | H38: 229
A39: =G39-D39 -> 1710.0016 | B39: =B40 -> 0 | C39: =C40 -> 0 | D39: =D40+C39 -> 0 | E39: =E40 -> 1710.0016 | F39: =F40 -> 0 | G39: =G40+F39 -> 1710.0016 | H39: 228
A40: =G40-D40 -> 1710.0016 | B40: =B41 -> 0 | C40: =C41 -> 0 | D40: =D41+C40 -> 0 | E40: =E41 -> 1710.0016 | F40: =F41 -> 0 | G40: =G41+F40 -> 1710.0016 | H40: 227
A41: =G41-D41 -> 1710.0016 | B41: =B42 -> 0 | C41: =C42 -> 0 | D41: =D42+C41 -> 0 | E41: =E42 -> 1710.0016 | F41: =F42 -> 0 | G41: =G42+F41 -> 1710.0016 | H41: 226
A42: =G42-D42 -> 1710.0016 | B42: =B43 -> 0 | C42: =C43 -> 0 | D42: =D43+C42 -> 0 | E42: =E43 -> 1710.0016 | F42: =F43 -> 0 | G42: =G43+F42 -> 1710.0016 | H42: 225
...

Sheet TABLE
A1: GPM | B1: SAND FILTRATION | K1: DEFENDER RMF
B2: QTY | C2: MODEL | D2: AREA | E2: MEDIA | F2: FOOTPRINT | G2: FILTER | H2: FACEPIPE | I2: AIR RELIEF | J2: TOTAL | K2: QTY | L2: MODEL | M2: AREA | N2: TK_VOL | O2: FOOTPRINT | P2: DEFENDER | Q2: VALVE | R2: TOTAL
D3: FT^2 | E3: LBS | F3: FT2 | G3: USD | H3: USD | I3: USD | J3: USD | M3: FT2 | N3: FT2 | O3: FT2 | P3: USD | Q3: USD | R3: USD
A4: 0
A5: 70 | B5: 1 | C5: 36CCFG | D5: 6.5 | E5: 800 | F5: 34 | G5: 2744.2197 | H5: 0 | I5: 248 | J5: =SUM(G5:I5) -> 2992.2197 | K5: 1 | L5: SP-29-36-200 | M5: 117 | N5: 181 | O5: 29 | P5: 20738 | Q5: 1940.05 | R5: =SUM(P5:Q5) -> 22678.05
A6: 86 | B6: 1 | C6: 42CCFG | D6: 9 | E6: 1200 | F6: 44 | G6: 3365.2903 | H6: 0 | I6: 248 | J6: =SUM(G6:I6) -> 3613.2903 | K6: 1 | L6: SP-29-36-200 | M6: 117 | N6: 181 | O6: 29 | P6: 20738 | Q6: 1940.05 | R6: =SUM(P6:Q6) -> 22678.05
A7: 116 | B7: 1 | C7: 48CCFG | D7: 11.8 | E7: 1900 | F7: 47 | G7: 4419.5857 | H7: 0 | I7: 248 | J7: =SUM(G7:I7) -> 4667.5857 | K7: 1 | L7: SP-29-36-200 | M7: 117 | N7: 181 | O7: 29 | P7: 20738 | Q7: 1940.05 | R7: =SUM(P7:Q7) -> 22678.05
A8: 146 | B8: 1 | C8: 34x48 | D8: 12.6 | E8: 1500 | F8: 40 | G8: 7811.49 | H8: 2646.424 | I8: 248 | J8: =SUM(G8:I8) -> 10705.914 | K8: 1 | L8: SP-29-36-250 | M8: 146 | N8: 181 | O8: 29 | P8: 24320 | Q8: 2090.06 | R8: =SUM(P8:Q8) -> 26410.06
A9: 161 | B9: 1 | C9: 34x54 | D9: 14 | E9: 1600 | F9: 41 | G9: 8206.96 | H9: 2646.424 | I9: 248 | J9: =SUM(G9:I9) -> 11101.384 | K9: 1 | L9: SP-29-36-250 | M9: 146 | N9: 181 | O9: 29 | P9: 24320 | Q9: 2090.06 | R9: =SUM(P9:Q9) -> 26410.06
A10: 176 | B10: 1 | C10: 34x60 | D10: 15.4 | E10: 1800 | F10: 42 | G10: 7926.73 | H10: 2646.424 | I10: 248 | J10: =SUM(G10:I10) -> 10821.154 | K10: 1 | L10: SP-29-36-300 | M10: 176 | N10: 181 | O10: 29 | P10: 27864 | Q10: 2090.06 | R10: =SUM(P10:Q10) -> 29954.06
A11: 193 | B11: 1 | C11: 42x48 | D11: 17.1 | E11: 2300 | F11: 45 | G11: 8190.14 | H11: 2646.424 | I11: 248 | J11: =SUM(G11:I11) -> 11084.564 | K11: 1 | L11: SP-29-36-300 | M11: 176 | N11: 181 | O11: 29 | P11: 27864 | Q11: 2090.06 | R11: =SUM(P11:Q11) -> 29954.06
A12: 221 | B12: 1 | C12: 42x60 | D12: 20.4 | E12: 2700 | F12: 63 | G12: 9029.2 | H12: 2646.424 | I12: 248 | J12: =SUM(G12:I12) -> 11923.624 | K12: 1 | L12: SP-29-36-350 | M12: 205 | N12: 181 | O12: 29 | P12: 32569 | Q12: 2090.06 | R12: =SUM(P12:Q12) -> 34659.06
A13: 251 | B13: 1 | C13: 42x72 | D13: 23.9 | E13: 3200 | F13: 69 | G13: 10769.5 | H13: 3592.336 | I13: 248 | J13: =SUM(G13:I13) -> 14609.836 | K13: 1 | L13: SP-29-36-400 | M13: 234 | N13: 181 | O13: 29 | P13: 39203 | Q13: 2258.72 | R13: =SUM(P13:Q13) -> 41461.72
A14: 313 | B14: 1 | C14: 48x72 | D14: 27.7 | E14: 4300 | F14: 70 | G14: 11260.29 | H14: 3592.336 | I14: 248 | J14: =SUM(G14:I14) -> 15100.626 | K14: 1 | L14: SP-29-36-500 | M14: 294 | N14: 181 | O14: 29 | P14: 41509 | Q14: 2258.72 | R14: =SUM(P14:Q14) -> 43767.72
A15: 376 | B15: 1 | C15: 48x84 | D15: 31.7 | E15: 4900 | F15: 75 | G15: 12689.32 | H15: 3592.336 | I15: 248 | J15: =SUM(G15:I15) -> 16529.656 | K15: 1 | L15: SP-27-48-487 | M15: 381 | N15: 159 | O15: 27 | P15: 53395 | Q15: 2476.07 | R15: =SUM(P15:Q15) -> 55871.07
A16: 431 | B16: 1 | C16: 48x96 | D16: 35.7 | E16: 5500 | F16: 82 | G16: 12960.65 | H16: 3592.336 | I16: 248 | J16: =SUM(G16:I16) -> 16800.986 | K16: 1 | L16: SP-27-48-487 | M16: 381 | N16: 159 | O16: 27 | P16: 53395 | Q16: 2476.07 | R16: =SUM(P16:Q16) -> 55871.07
... A36: 4079 | B36: 6 | C36: 60x108 | D36: 334.8 | E36: 65400 | F36: 345 | G36: 121529.94 | H36: 34485 | I36: 744 | J36: =SUM(G36:I36) -> 156758.94 | K36: 2 | L36: SP-55-48-2076 | M36: 3250 | N36: 1682 | O36: 144 | P36: 289290 | Q36: 15206.8 | R36: =SUM(P36:Q36) -> 304496.8
A37: 4551 | L37: SP-55-48-2076 | M37: 3250 | N37: 1682
J39: Compressor | L39: 12213 | P39: 1379.9541 | R39: =SUM(P39:Q39) -> 1379.9541
J40: Toolk Kit | L40: 11737 | P40: 330.04743 | R40: =SUM(P40:Q40) -> 330.04743
